Workbook
Name Slicer_Income_Group: #N/A
Name Slicer_Region: #N/A

Sheet Index
B2: GLOBAL ARMS TRANSFERS & DEFENSE POLICY (2000–2024)
B3: Workbook Navigation Index & Analytical Directory | Master Dataset Architecture
B5: Sheet Name | C5: Description
B6: Imports_Raw | C6: Raw World Bank / SIPRI arms imports records
B7: Exports_Raw | C7: Raw World Bank / SIPRI arms exports records
B8: Clean_Data | C8: 3,985 dyadic observations, enriched metadata, net trade calculations
B9: Analysis | C9: Macro KPIs, Top 10 rankings, regional balances, 25-yr supplier trajectory
B10: Dashboard | C10: Three-panel visual dashboard (trends, volumes, regional diverging balances)
B11: Pivot_Table | C11: Income tier cross-tabulation with dynamic region slicers
B12: Data_Dictionary | C12: Complete variable schemas, indicators, and methodology notes

Sheet Imports_Raw
A1: Data Source | B1: World Development Indicators
A3: Last Updated Date | B3: 46303
A5: Country Name | B5: Country Code | C5: Indicator Name | D5: Indicator Code | E5: 1960 | F5: 1961 | G5: 1962 | H5: 1963 | I5: 1964 | J5: 1965 | K5: 1966 | L5: 1967 | M5: 1968 | N5: 1969 | O5: 1970 | P5: 1971 | Q5: 1972 | R5: 1973 | S5: 1974 | T5: 1975 | U5: 1976 | V5: 1977 | W5: 1978 | X5: 1979 | Y5: 1980 | Z5: 1981 | AA5: 1982 | AB5: 1983 | AC5: 1984 | AD5: 1985 | AE5: 1986 | AF5: 1987 | AG5: 1988 | AH5: 1989 | AI5: 1990 | AJ5: 1991 | AK5: 1992 | AL5: 1993 | AM5: 1994 | AN5: 1995 | AO5: 1996 | AP5: 1997 | AQ5: 1998 | AR5: 1999 | AS5: 2000 | AT5: 2001 | AU5: 2002 | AV5: 2003 | AW5: 2004 | AX5: 2005 | AY5: 2006 | AZ5: 2007 | BA5: 2008 | BB5: 2009 | BC5: 2010 | BD5: 2011 | BE5: 2012 | BF5: 2013 | BG5: 2014 | BH5: 2015 | BI5: 2016 | BJ5: 2017 | BK5: 2018 | BL5: 2019 | BM5: 2020 | BN5: 2021 | BO5: 2022 | BP5: 2023 | BQ5: 2024 | BR5: 2025
A6: Aruba | B6: ABW | C6: Arms imports (SIPRI trend indicator values) | D6: MS.MIL.MPRT.KD
A7: Africa Eastern and Southern | B7: AFE | C7: Arms imports (SIPRI trend indicator values) | D7: MS.MIL.MPRT.KD | E7: 71000000 | G7: 327000000 | H7: 628000000 | I7: 431000000 | J7: 503000000 | K7: 768000000 | L7: 466000000 | M7: 305000000 | N7: 471000000 | O7: 1236000000 | P7: 874000000 | Q7: 582000000 | R7: 728000000 | S7: 799000000 | T7: 1427000000 | U7: 1260000000 | V7: 2173000000 | W7: 2628000000 | X7: 1048000000 | Y7: 1181000000 | Z7: 1650000000 | AA7: 1372000000 | AB7: 1386000000 | AC7: 1132000000 | AD7: 1077000000 | AE7: 1552000000 | AF7: 1877000000 | AG7: 1269000000 | AH7: 323000000 | AI7: 273000000 | AJ7: 224000000 | AL7: 401000000 | AM7: 413000000 | AN7: 97000000 | AO7: 312000000 | AP7: 350000000 | AS7: 522000000 | AT7: 403000000 | AX7: 598000000 | AY7: 1035000000 | AZ7: 1081000000 | BA7: 768000000 | BB7: 420000000 | BD7: 1131000000 | BE7: 988000000 | BF7: 563000000 | BG7: 308000000 | BH7: 330000000 | BO7: 259000000 | BP7: 166000000 | BR7: 420000000
A8: Afghanistan | B8: AFG | C8: Arms imports (SIPRI trend indicator values) | D8: MS.MIL.MPRT.KD | E8: 39000000 | F8: 55000000 | G8: 64000000 | H8: 40000000 | I8: 56000000 | J8: 91000000 | K8: 198000000 | L8: 230000000 | M8: 145000000 | N8: 166000000 | O8: 120000000 | P8: 25000000 | S8: 47000000 | T8: 137000000 | U8: 230000000 | V8: 75000000 | W8: 156000000 | X8: 449000000 | Y8: 632000000 | Z8: 553000000 | AA8: 455000000 | AB8: 269000000 | AC8: 394000000 | AD8: 158000000 | AE8: 210000000 | AF8: 489000000 | AG8: 927000000 | AH8: 1820000000 | AI8: 1612000000 | AJ8: 1236000000 | AU8: 34000000 | AX8: 33000000 | AY8: 3000000 | AZ8: 40000000 | BA8: 148000000 | BB8: 326000000 | BC8: 365000000 | BD8: 632000000 | BE8: 518000000 | BF8: 253000000 | BG8: 323000000 | BH8: 131000000 | BI8: 170000000 | BJ8: 235000000 | BK8: 312000000 | BL8: 379000000 | BM8: 231000000 | BN8: 65000000
A9: Africa Western and Central | B9: AFW | C9: Arms imports (SIPRI trend indicator values) | D9: MS.MIL.MPRT.KD | E9: 51000000 | F9: 136000000 | G9: 41000000 | H9: 28000000 | I9: 56000000 | J9: 119000000 | K9: 195000000 | L9: 92000000 | M9: 89000000 | N9: 113000000 | O9: 57000000 | P9: 155000000 | Q9: 135000000 | R9: 93000000 | S9: 162000000 | U9: 442000000 | V9: 304000000 | W9: 427000000 | X9: 416000000 | Y9: 709000000 | Z9: 609000000 | AA9: 854000000 | AB9: 226000000 | AC9: 673000000 | AD9: 611000000 | AE9: 372000000 | AF9: 217000000 | AG9: 159000000 | AH9: 194000000 | AI9: 146000000 | AM9: 136000000 | AP9: 85000000 | AS9: 111000000 | AT9: 56000000 | AU9: 84000000 | AV9: 159000000 | AW9: 83000000 | AY9: 102000000 | AZ9: 181000000 | BA9: 164000000 | BB9: 219000000 | BC9: 367000000 | BD9: 253000000 | BE9: 224000000 | BF9: 342000000 | BG9: 580000000 | BH9: 265000000 | BI9: 223000000 | BJ9: 157000000 | BK9: 159000000 | BL9: 189000000 | BM9: 205000000 | BN9: 499000000 | BO9: 324000000 | BP9: 587000000 | BQ9: 433000000 | BR9: 163000000
A10: Angola | B10: AGO | C10: Arms imports (SIPRI trend indicator values) | D10: MS.MIL.MPRT.KD | S10: 1000000 | T10: 233000000 | U10: 192000000 | V10: 134000000 | W10: 133000000 | X10: 116000000 | Y10: 116000000 | Z10: 264000000 | AA10: 344000000 | AB10: 589000000 | AC10: 501000000 | AD10: 536000000 | AE10: 710000000 | AF10: 1193000000 | AG10: 971000000 | AH10: 152000000 | AI10: 140000000 | AL10: 123000000 | AM10: 113000000 | AN10: 1000000 | AO10: 44000000 | AP10: 7000000 | AQ10: 150000000 | AR10: 360000000 | AS10: 149000000 | AT10: 157000000 | AU10: 148000000 | AV10: 48000000 | AW10: 8000000 | AX10: 38000000 | AY10: 7000000 | AZ10: 35000000 | BA10: 29000000 | BB10: 20000000 | BF10: 31000000 | BG10: 2000000 | BH10: 49000000 | BI10: 156000000 | BJ10: 113000000 | BK10: 274000000 | BL10: 170000000 | BM10: 51000000 | BO10: 46000000 | BP10: 15000000 | BQ10: 16000000 | BR10: 84000000
A11: Albania | B11: ALB | C11: Arms imports (SIPRI trend indicator values) | D11: MS.MIL.MPRT.KD | E11: 69000000 | F11: 74000000 | G11: 42000000 | H11: 12000000 | I11: 8000000 | J11: 140000000 | K11: 74000000 | L11: 163000000 | M11: 265000000 | N11: 297000000 | O11: 250000000 | P11: 332000000 | Q11: 134000000 | R11: 106000000 | S11: 137000000 | T11: 53000000 | U11: 5000000 | V11: 7000000 | W11: 5000000 | AN11: 26000000 | AV11: 2000000 | AX11: 7000000 | AZ11: 5000000 | BE11: 15000000 | BF11: 7000000 | BG11: 7000000 | BH11: 7000000 | BJ11: 1000000 | BK11: 1000000 | BL11: 5000000 | BM11: 12000000 | BN11: 1000000 | BP11: 1000000 | BQ11: 38000000 | BR11: 23000000
A12: Andorra | B12: AND | C12: Arms imports (SIPRI trend indicator values) | D12: MS.MIL.MPRT.KD
A13: Arab World | B13: ARB | C13: Arms imports (SIPRI trend indicator values) | D13: MS.MIL.MPRT.KD | E13: 581000000 | F13: 831000000 | G13: 1302000000 | H13: 1244000000 | I13: 1585000000 | J13: 1994000000 | K13: 3500000000 | L13: 4714000000 | M13: 3360000000 | N13: 3774000000 | O13: 4563000000 | P13: 3880000000 | Q13: 6573000000 | R13: 9290000000 | S13: 9119000000 | T13: 6348000000 | U13: 5998000000 | V13: 9678000000 | W13: 11448000000 | X13: 11375000000 | Y13: 11924000000 | Z13: 13660000000 | AA13: 16619000000 | AB13: 13760000000 | AC13: 12620000000 | AD13: 10621000000 | AE13: 10284000000 | AF13: 10073000000 | AG13: 5539000000 | AH13: 5810000000 | AI13: 6492000000 | AJ13: 4401000000 | AK13: 3752000000 | AL13: 5286000000 | AM13: 4188000000 | AN13: 4778000000 | AO13: 5332000000 | AP13: 6086000000 | AQ13: 4929000000 | AR13: 3466000000 | AS13: 2744000000 | AT13: 2105000000 | AU13: 2901000000 | AV13: 2379000000 | AW13: 4076000000 | AX13: 4497000000 | AY13: 4198000000 | AZ13: 3237000000 | BA13: 4160000000 | BB13: 4126000000 | BC13: 5446000000 | BD13: 7377000000 | BE13: 6034000000 | BF13: 7185000000 | BG13: 7631000000 | BH13: 10490000000 | BI13: 12782000000 | BJ13: 11766000000 | BK13: 9651000000 | BL13: 8120000000 | BM13: 6474000000 | BN13: 8071000000 | BO13: 10869000000 | BP13: 7241000000 | BQ13: 5605000000 | BR13: 6625000000
A14: United Arab Emirates | B14: ARE | C14: Arms imports (SIPRI trend indicator values) | D14: MS.MIL.MPRT.KD | M14: 13000000 | N14: 12000000 | O14: 67000000 | P14: 24000000 | Q14: 28000000 | R14: 88000000 | S14: 100000000 | T14: 145000000 | U14: 275000000 | V14: 310000000 | W14: 230000000 | X14: 39000000 | Y14: 213000000 | Z14: 420000000 | AA14: 155000000 | AB14: 163000000 | AC14: 310000000 | AD14: 145000000 | AE14: 132000000 | AF14: 195000000 | AG14: 45000000 | AH14: 663000000 | AI14: 561000000 | AJ14: 237000000 | AK14: 205000000 | AL14: 582000000 | AM14: 571000000 | AN14: 426000000 | AO14: 481000000 | AP14: 690000000 | AQ14: 757000000 | AR14: 441000000 | AS14: 244000000 | AT14: 186000000 | AU14: 223000000 | AV14: 676000000 | AW14: 1145000000 | AX14: 2072000000 | AY14: 1925000000 | AZ14: 819000000 | BA14: 730000000 | BB14: 604000000 | BC14: 650000000 | BD14: 1217000000 | BE14: 1139000000 | BF14: 2324000000 | BG14: 736000000 | BH14: 1691000000 | BI14: 1491000000 | BJ14: 909000000 | BK14: 1165000000 | BL14: 750000000 | BM14: 660000000 | BN14: 577000000 | BO14: 756000000 | BP14: 918000000 | BQ14: 1086000000 | BR14: 868000000
A15: Argentina | B15: ARG | C15: Arms imports (SIPRI trend indicator values) | D15: MS.MIL.MPRT.KD | E15: 111000000 | F15: 205000000 | G15: 47000000 | H15: 29000000 | I15: 19000000 | J15: 7000000 | K15: 93000000 | L15: 143000000 | M15: 430000000 | N15: 230000000 | O15: 257000000 | P15: 363000000 | Q15: 402000000 | R15: 248000000 | S15: 450000000 | T15: 268000000 | U15: 499000000 | V15: 204000000 | W15: 434000000 | X15: 451000000 | Y15: 445000000 | Z15: 833000000 | AA15: 406000000 | AB15: 1309000000 | AC15: 724000000 | AD15: 485000000 | AE15: 219000000 | AF15: 217000000 | AG15: 71000000 | AH15: 6000000 | AI15: 159000000 | AK15: 27000000 | AM15: 209000000 | AN15: 43000000 | AO15: 21000000 | AP15: 105000000 | AQ15: 171000000 | AR15: 276000000 | AS15: 208000000 | AT15: 6000000 | AU15: 15000000 | AV15: 11000000 | AW15: 161000000 | AX15: 3000000 | AY15: 9000000 | AZ15: 24000000 | BA15: 21000000 | BB15: 15000000 | BC15: 11000000 | BD15: 16000000 | BE15: 5000000 | BF15: 13000000 | BG15: 6000000 | BH15: 18000000 | BI15: 17000000 | BJ15: 47000000 | BK15: 19000000 | BL15: 51000000 | BM15: 7000000 | BN15: 77000000 | BO15: 50000000 | BP15: 22000000 | BQ15: 45000000 | BR15: 108000000
A16: Armenia | B16: ARM | C16: Arms imports (SIPRI trend indicator values) | D16: MS.MIL.MPRT.KD | AL16: 2000000 | AM16: 181000000 | AN16: 47000000 | AO16: 68000000 | AR16: 2000000 | AW16: 118000000 | AZ16: 1000000 | BB16: 46000000 | BC16: 52000000 | BD16: 5000000 | BF16: 52000000 | BI16: 112000000 | BJ16: 22000000 | BL16: 248000000 | BN16: 32000000 | BO16: 29000000 | BP16: 7000000 | BQ16: 32000000 | BR16: 21000000
A17: American Samoa | B17: ASM | C17: Arms imports (SIPRI trend indicator values) | D17: MS.MIL.MPRT.KD
A18: Antigua and Barbuda | B18: ATG | C18: Arms imports (SIPRI trend indicator values) | D18: MS.MIL.MPRT.KD | BO18: 0 | BP18: 0
A19: Australia | B19: AUS | C19: Arms imports (SIPRI trend indicator values) | D19: MS.MIL.MPRT.KD | E19: 116000000 | F19: 155000000 | G19: 460000000 | H19: 369000000 | I19: 539000000 | J19: 920000000 | K19: 707000000 | L19: 770000000 | M19: 557000000 | N19: 702000000 | O19: 230000000 | P19: 310000000 | Q19: 63000000 | R19: 713000000 | S19: 898000000 | T19: 108000000 | U19: 91000000 | V19: 278000000 | W19: 1029000000 | X19: 197000000 | Y19: 409000000 | Z19: 449000000 | AA19: 134000000 | AB19: 637000000 | AC19: 635000000 | AD19: 510000000 | AE19: 815000000 | AF19: 594000000 | AG19: 745000000 | AH19: 695000000 | AI19: 356000000 | AJ19: 219000000 | AK19: 364000000 | AL19: 448000000 | AM19: 262000000 | AN19: 64000000 | AO19: 597000000 | AP19: 35000000 | AQ19: 542000000 | AR19: 678000000 | AS19: 326000000 | AT19: 1215000000 | AU19: 638000000 | AV19: 765000000 | AW19: 447000000 | AX19: 458000000 | AY19: 721000000 | AZ19: 618000000 | BA19: 430000000 | BB19: 805000000 | BC19: 1558000000 | BD19: 1582000000 | BE19: 787000000 | BF19: 220000000 | BG19: 848000000 | BH19: 1445000000 | BI19: 1012000000 | BJ19: 1664000000 | BK19: 1553000000 | BL19: 1159000000 | BM19: 1632000000 | BN19: 1218000000 | BO19: 809000000 | BP19: 376000000 | BQ19: 1077000000 | BR19: 826000000
A20: Austria | B20: AUT | C20: Arms imports (SIPRI trend indicator values) | D20: MS.MIL.MPRT.KD | E20: 16000000 | F20: 27000000 | G20: 56000000 | H20: 201000000 | I20: 74000000 | J20: 78000000 | K20: 61000000 | L20: 48000000 | M20: 1000000 | N20: 12000000 | O20: 99000000 | P20: 123000000 | Q20: 93000000 | R20: 38000000 | S20: 32000000 | T20: 12000000 | U20: 12000000 | W20: 8000000 | X20: 72000000 | Y20: 177000000 | Z20: 73000000 | AA20: 97000000 | AB20: 145000000 | AC20: 13000000 | AD20: 28000000 | AE20: 19000000 | AF20: 7000000 | AG20: 117000000 | AH20: 84000000 | AI20: 5000000 | AJ20: 6000000 | AK20: 5000000 | AL20: 8000000 | AM20: 52000000 | AN20: 30000000 | AO20: 9000000 | AP20: 190000000 | AQ20: 247000000 | AR20: 48000000 | AS20: 25000000 | AT20: 15000000 | AU20: 81000000 | AV20: 41000000 | AW20: 56000000 | AX20: 26000000 | AY20: 5000000 | AZ20: 269000000 | BA20: 190000000 | BB20: 286000000 | BC20: 5000000 | BD20: 6000000 | BE20: 6000000 | BF20: 5000000 | BG20: 2000000 | BH20: 1000000 | BI20: 13000000 | BJ20: 10000000 | BK20: 6000000 | BL20: 18000000 | BM20: 14000000 | BN20: 34000000 | BO20: 5000000 | BP20: 17000000 | BQ20: 13000000 | BR20: 29000000
A21: Azerbaijan | B21: AZE | C21: Arms imports (SIPRI trend indicator values) | D21: MS.MIL.MPRT.KD | AL21: 50000000 | AM21: 25000000 | AS21: 3000000 | AU21: 89000000 | AW21: 4000000 | AX21: 63000000 | AY21: 168000000 | AZ21: 213000000 | BA21: 34000000 | BB21: 147000000 | BC21: 163000000 | BD21: 569000000 | BE21: 397000000 | BF21: 398000000 | BG21: 642000000 | BH21: 351000000 | BI21: 287000000 | BJ21: 290000000 | BK21: 375000000 | BL21: 44000000 | BM21: 51000000 | BO21: 9000000 | BP21: 3000000 | BQ21: 75000000 | BR21: 463000000
A22: Burundi | B22: BDI | C22: Arms imports (SIPRI trend indicator values) | D22: MS.MIL.MPRT.KD | K22: 9000000 | L22: 2000000 | N22: 3000000 | R22: 0 | Y22: 1000000 | Z22: 5000000 | AA22: 3000000 | AB22: 11000000 | AC22: 2000000 | AH22: 6000000 | AI22: 6000000 | AQ22: 12000000 | AT22: 1000000 | AU22: 3000000 | BB22: 1000000 | BC22: 2000000 | BE22: 5000000 | BH22: 1000000 | BI22: 3000000 | BL22: 2000000
A23: Belgium | B23: BEL | C23: Arms imports (SIPRI trend indicator values) | D23: MS.MIL.MPRT.KD | E23: 92000000 | F23: 132000000 | G23: 188000000 | H23: 575000000 | I23: 652000000 | J23: 521000000 | K23: 116000000 | L23: 39000000 | M23: 220000000 | N23: 240000000 | O23: 514000000 | P23: 499000000 | Q23: 492000000 | R23: 562000000 | S23: 113000000 | T23: 130000000 | U23: 184000000 | V23: 187000000 | W23: 409000000 | X23: 779000000 | Y23: 565000000 | Z23: 515000000 | AA23: 433000000 | AB23: 580000000 | AC23: 575000000 | AD23: 287000000 | AE23: 91000000 | AF23: 91000000 | AG23: 407000000 | AH23: 203000000 | AI23: 314000000 | AJ23: 125000000 | AK23: 48000000 | AL23: 73000000 | AM23: 47000000 | AN23: 16000000 | AO23: 3000000 | AP23: 50000000 | AQ23: 55000000 | AR23: 58000000 | AS23: 36000000 | AT23: 30000000 | AU23: 48000000 | AV23: 21000000 | AW23: 15000000 | AX23: 3000000 | AY23: 15000000 | AZ23: 171000000 | BA23: 191000000 | BB23: 87000000 | BC23: 40000000 | BD23: 27000000 | BE23: 33000000 | BF23: 48000000 | BG23: 99000000 | BH23: 52000000 | BI23: 4000000 | BJ23: 7000000 | BK23: 1000000 | BL23: 9000000 | BM23: 90000000 | BN23: 255000000 | BO23: 170000000 | BP23: 12000000 | BQ23: 508000000 | BR23: 430000000
A24: Benin | B24: BEN | C24: Arms imports (SIPRI trend indicator values) | D24: MS.MIL.MPRT.KD | F24: 2000000 | G24: 1000000 | I24: 2000000 | K24: 1000000 | O24: 0 | P24: 2000000 | R24: 1000000 | W24: 26000000 | X24: 6000000 | AA24: 10000000 | AB24: 3000000 | AC24: 1000000 | AD24: 3000000 | AF24: 1000000 | AG24: 0 | AH24: 0 | AU24: 7000000 | AZ24: 3000000 | BB24: 1000000 | BC24: 0 | BD24: 0 | BE24: 20000000 | BF24: 3000000 | BI24: 1000000 | BM24: 1000000 | BO24: 3000000 | BP24: 12000000 | BQ24: 7000000 | BR24: 4000000
A25: Burkina Faso | B25: BFA | C25: Arms imports (SIPRI trend indicator values) | D25: MS.MIL.MPRT.KD | F25: 1000000 | I25: 1000000 | J25: 0 | K25: 0 | M25: 0 | N25: 1000000 | O25: 1000000 | P25: 1000000 | T25: 14000000 | U25: 8000000 | V25: 9000000 | Y25: 0 | Z25: 9000000 | AA25: 1000000 | AB25: 16000000 | AC25: 9000000 | AD25: 2000000 | AE25: 3000000 | AG25: 12000000 | AJ25: 4000000 | AL25: 7000000 | AR25: 0 | AX25: 12000000 | AY25: 4000000 | AZ25: 4000000 | BB25: 3000000 | BC25: 0 | BD25: 16000000 | BE25: 3000000 | BH25: 5000000 | BI25: 7000000 | BJ25: 2000000 | BK25: 24000000 | BL25: 7000000 | BM25: 3000000 | BN25: 26000000 | BO25: 12000000 | BP25: 19000000 | BQ25: 37000000 | BR25: 34000000
A26: Bangladesh | B26: BGD | C26: Arms imports (SIPRI trend indicator values) | D26: MS.MIL.MPRT.KD | P26: 10000000 | Q26: 2000000 | R26: 76000000 | S26: 44000000 | T26: 39000000 | U26: 70000000 | V26: 62000000 | W26: 45000000 | X26: 1000000 | Y26: 55000000 | Z26: 72000000 | AA26: 128000000 | AB26: 109000000 | AC26: 9000000 | AD26: 124000000 | AE26: 4000000 | AF26: 1000000 | AG26: 242000000 | AH26: 302000000 | AI26: 199000000 | AJ26: 79000000 | AK26: 113000000 | AL26: 49000000 | AM26: 61000000 | AN26: 123000000 | AO26: 7000000 | AP26: 26000000 | AQ26: 1000000 | AR26: 184000000 | AS26: 200000000 | AT26: 274000000 | AU26: 37000000 | AV26: 8000000 | AW26: 32000000 | AX26: 10000000 | AY26: 221000000 | AZ26: 82000000 | BA26: 12000000 | BC26: 36000000 | BD26: 120000000 | BE26: 199000000 | BF26: 648000000 | BG26: 207000000 | BH26: 638000000 | BI26: 455000000 | BJ26: 334000000 | BK26: 161000000 | BL26: 713000000 | BM26: 70000000 | BN26: 60000000 | BO26: 331000000 | BP26: 74000000 | BQ26: 70000000 | BR26: 32000000
A27: Bulgaria | B27: BGR | C27: Arms imports (SIPRI trend indicator values) | D27: MS.MIL.MPRT.KD | E27: 482000000 | F27: 522000000 | G27: 493000000 | H27: 553000000 | I27: 326000000 | J27: 372000000 | K27: 218000000 | L27: 329000000 | M27: 256000000 | N27: 533000000 | O27: 771000000 | P27: 407000000 | Q27: 460000000 | R27: 274000000 | S27: 302000000 | T27: 390000000 | U27: 368000000 | V27: 492000000 | W27: 876000000 | X27: 323000000 | Y27: 580000000 | Z27: 984000000 | AA27: 610000000 | AB27: 754000000 | AC27: 945000000 | AD27: 619000000 | AE27: 932000000 | AF27: 449000000 | AG27: 253000000 | AH27: 314000000 | AI27: 755000000 | AJ27: 339000000 | AK27: 42000000 | AL27: 1000000 | AM27: 1000000 | AN27: 1000000 | AO27: 122000000 | AR27: 7000000 | AV27: 2000000 | AW27: 13000000 | AX27: 132000000 | AY27: 22000000 | AZ27: 48000000 | BA27: 117000000 | BB27: 119000000 | BC27: 8000000 | BD27: 29000000 | BE27: 5000000 | BH27: 4000000 | BL27: 2000000 | BM27: 44000000 | BN27: 1000000 | BO27: 3000000 | BR27: 540000000
A28: Bahrain | B28: BHR | C28: Arms imports (SIPRI trend indicator values) | D28: MS.MIL.MPRT.KD | P28: 0 | Q28: 7000000 | R28: 0 | S28: 1000000 | V28: 2000000 | W28: 12000000 | X28: 10000000 | Y28: 22000000 | Z28: 40000000 | AA28: 55000000 | AB28: 10000000 | AC28: 129000000 | AD28: 55000000 | AE28: 133000000 | AF28: 249000000 | AG28: 135000000 | AH28: 66000000 | AI28: 362000000 | AJ28: 68000000 | AK28: 51000000 | AL28: 1000000 | AM28: 8000000 | AN28: 71000000 | AO28: 51000000 | AP28: 197000000 | AQ28: 8000000 | AS28: 299000000 | AT28: 28000000 | AU28: 52000000 | AV28: 1000000 | AW28: 10000000 | AX28: 66000000 | AY28: 63000000 | AZ28: 27000000 | BA28: 21000000 | BC28: 98000000 | BD28: 4000000 | BE28: 24000000 | BF28: 69000000 | BG28: 1000000 | BH28: 17000000 | BI28: 30000000 | BJ28: 27000000 | BK28: 72000000 | BL28: 21000000 | BM28: 27000000 | BN28: 184000000 | BO28: 259000000 | BP28: 294000000 | BQ28: 850000000 | BR28: 30000000
A29: Bahamas, The | B29: BHS | C29: Arms imports (SIPRI trend indicator values) | D29: MS.MIL.MPRT.KD | W29: 11000000 | AE29: 33000000 | AI29: 2000000 | AJ29: 3000000 | AS29: 33000000 | AX29: 3000000 | BB29: 1000000 | BG29: 30000000 | BH29: 16000000 | BI29: 20000000 | BJ29: 12000000
A30: Bosnia and Herzegovina | B30: BIH | C30: Arms imports (SIPRI trend indicator values) | D30: MS.MIL.MPRT.KD | AL30: 6000000 | AM30: 6000000 | AO30: 58000000 | AP30: 78000000 | AQ30: 2000000 | AR30: 25000000 | BJ30: 0 | BL30: 0 | BM30: 0 | BN30: 12000000 | BR30: 1000000
A31: Belarus | B31: BLR | C31: Arms imports (SIPRI trend indicator values) | D31: MS.MIL.MPRT.KD | AQ31: 41000000 | AR31: 41000000 | AX31: 6000000 | AY31: 140000000 | BB31: 3000000 | BD31: 75000000 | BE31: 75000000 | BF31: 75000000 | BG31: 66000000 | BH31: 98000000 | BI31: 120000000 | BJ31: 158000000 | BK31: 142000000 | BL31: 333000000 | BM31: 13000000 | BN31: 69000000 | BO31: 215000000 | BP31: 178000000 | BQ31: 399000000 | BR31: 466000000
A32: Belize | B32: BLZ | C32: Arms imports (SIPRI trend indicator values) | D32: MS.MIL.MPRT.KD | AC32: 0 | AO32: 0 | AS32: 1000000 | BI32: 2000000 | BP32: 1000000
A33: Bermuda | B33: BMU | C33: Arms imports (SIPRI trend indicator values) | D33: MS.MIL.MPRT.KD
A34: Bolivia | B34: BOL | C34: Arms imports (SIPRI trend indicator values) | D34: MS.MIL.MPRT.KD | E34: 6000000 | F34: 4000000 | G34: 2000000 | H34: 4000000 | I34: 2000000 | J34: 2000000 | K34: 1000000 | L34: 14000000 | M34: 17000000 | N34: 1000000 | O34: 2000000 | P34: 2000000 | Q34: 12000000 | R34: 16000000 | S34: 23000000 | T34: 17000000 | U34: 16000000 | V34: 1000000 | W34: 11000000 | X34: 53000000 | Y34: 40000000 | Z34: 28000000 | AA34: 2000000 | AD34: 18000000 | AE34: 15000000 | AG34: 56000000 | AH34: 66000000 | AJ34: 11000000 | AK34: 25000000 | AL34: 16000000 | AM34: 9000000 | AN34: 2000000 | AR34: 9000000 | AS34: 19000000 | AV34: 5000000 | AW34: 1000000 | AX34: 1000000 | AY34: 9000000 | AZ34: 2000000 | BA34: 3000000 | BB34: 6000000 | BC34: 1000000 | BD34: 25000000 | BE34: 12000000 | BF34: 1000000 | BG34: 46000000 | BI34: 27000000 | BJ34: 7000000 | BK34: 2000000 | BL34: 34000000 | BM34: 26000000 | BQ34: 0
A35: Brazil | B35: BRA | C35: Arms imports (SIPRI trend indicator values) | D35: MS.MIL.MPRT.KD | E35: 236000000 | F35: 212000000 | G35: 62000000 | H35: 127000000 | I35: 25000000 | J35: 149000000 | K35: 57000000 | L35: 218000000 | M35: 236000000 | N35: 108000000 | O35: 217000000 | P35: 171000000 | Q35: 520000000 | R35: 598000000 | S35: 256000000 | T35: 538000000 | U35: 551000000 | V35: 525000000 | W35: 832000000 | X35: 375000000 | Y35: 338000000 | Z35: 61000000 | AA35: 72000000 | AB35: 88000000 | AC35: 123000000 | AD35: 82000000 | AE35: 139000000 | AF35: 234000000 | AG35: 125000000 | AH35: 742000000 | AI35: 140000000 | AJ35: 161000000 | AK35: 98000000 | AL35: 66000000 | AM35: 311000000 | AN35: 267000000 | AO35: 547000000 | AP35: 476000000 | AQ35: 200000000 | AR35: 308000000 | AS35: 86000000 | AT35: 573000000 | AU35: 221000000 | AV35: 110000000 | AW35: 85000000 | AX35: 223000000 | AY35: 178000000 | AZ35: 188000000 | BA35: 178000000 | BB35: 135000000 | BC35: 256000000 | BD35: 231000000 | BE35: 317000000 | BF35: 217000000 | BG35: 201000000 | BH35: 202000000 | BI35: 111000000 | BJ35: 96000000 | BK35: 258000000 | BL35: 125000000 | BM35: 134000000 | BN35: 240000000 | BO35: 469000000 | BP35: 193000000 | BQ35: 450000000 | BR35: 462000000
A36: Barbados | B36: BRB | C36: Arms imports (SIPRI trend indicator values) | D36: MS.MIL.MPRT.KD | Z36: 9000000 | AC36: 1000000 | AZ36: 10000000 | BA36: 10000000 | BB36: 10000000
A37: Brunei Darussalam | B37: BRN | C37: Arms imports (SIPRI trend indicator values) | D37: MS.MIL.MPRT.KD | J37: 5000000 | K37: 1000000 | L37: 18000000 | M37: 1000000 | O37: 5000000 | P37: 18000000 | Q37: 1000000 | R37: 1000000 | S37: 15000000 | T37: 1000000 | U37: 0 | W37: 46000000 | X37: 64000000 | Z37: 8000000 | AA37: 12000000 | AB37: 85000000 | AC37: 60000000 | AE37: 13000000 | AI37: 4000000 | AJ37: 4000000 | AO37: 17000000 | AP37: 31000000 | AQ37: 7000000 | AR37: 4000000 | AT37: 5000000 | AU37: 1000000 | AV37: 0 | AW37: 0 | AX37: 1000000 | AY37: 1000000 | BB37: 33000000 | BC37: 33000000 | BD37: 229000000 | BE37: 20000000 | BF37: 15000000 | BG37: 121000000 | BH37: 36000000 | BP37: 11000000 | BQ37: 28000000
A38: Bhutan | B38: BTN | C38: Arms imports (SIPRI trend indicator values) | D38: MS.MIL.MPRT.KD | M38: 1000000 | AW38: 0 | BH38: 1000000 | BI38: 1000000 | BN38: 5000000
A39: Botswana | B39: BWA | C39: Arms imports (SIPRI trend indicator values) | D39: MS.MIL.MPRT.KD | V39: 1000000 | W39: 1000000 | X39: 7000000 | Y39: 2000000 | Z39: 11000000 | AD39: 5000000 | AF39: 26000000 | AG39: 40000000 | AH39: 4000000 | AI39: 22000000 | AJ39: 2000000 | AK39: 2000000 | AL39: 11000000 | AN39: 12000000 | AO39: 32000000 | AP39: 71000000 | AQ39: 2000000 | AS39: 54000000 | AT39: 15000000 | AU39: 1000000 | AV39: 11000000 | AW39: 10000000 | BB39: 10000000 | BC39: 10000000 | BE39: 6000000 | BF39: 8000000 | BI39: 5000000 | BK39: 5000000 | BL39: 7000000 | BM39: 76000000 | BN39: 16000000 | BO39: 11000000 | BP39: 1000000 | BQ39: 11000000
A40: Central African Republic | B40: CAF | C40: Arms imports (SIPRI trend indicator values) | D40: MS.MIL.MPRT.KD | F40: 2000000 | J40: 1000000 | K40: 2000000 | M40: 3000000 | P40: 2000000 | R40: 0 | W40: 0 | Y40: 0 | Z40: 1000000 | AA40: 3000000 | AB40: 6000000 | AC40: 1000000 | AD40: 6000000 | AG40: 2000000 | AK40: 1000000 | AY40: 9000000 | BA40: 0 | BD40: 7000000 | BK40: 2000000 | BM40: 1000000 | BN40: 44000000 | BO40: 2000000 | BP40: 43000000
A41: Canada | B41: CAN | C41: Arms imports (SIPRI trend indicator values) | D41: MS.MIL.MPRT.KD | E41: 171000000 | F41: 1576000000 | G41: 1220000000 | H41: 1012000000 | I41: 742000000 | J41: 563000000 | K41: 306000000 | L41: 237000000 | M41: 336000000 | N41: 516000000 | O41: 623000000 | P41: 457000000 | Q41: 376000000 | R41: 78000000 | S41: 229000000 | T41: 195000000 | U41: 53000000 | V41: 90000000 | W41: 130000000 | X41: 193000000 | Y41: 442000000 | Z41: 453000000 | AA41: 277000000 | AB41: 649000000 | AC41: 654000000 | AD41: 848000000 | AE41: 849000000 | AF41: 787000000 | AG41: 712000000 | AH41: 37000000 | AI41: 157000000 | AJ41: 767000000 | AK41: 407000000 | AL41: 196000000 | AM41: 473000000 | AN41: 405000000 | AO41: 419000000 | AP41: 353000000 | AQ41: 111000000 | AR41: 143000000 | AS41: 529000000 | AT41: 520000000 | AU41: 418000000 | AV41: 140000000 | AW41: 341000000 | AX41: 106000000 | AY41: 97000000 | AZ41: 478000000 | BA41: 423000000 | BB41: 104000000 | BC41: 242000000 | BD41: 356000000 | BE41: 207000000 | BF41: 202000000 | BG41: 316000000 | BH41: 408000000 | BI41: 246000000 | BJ41: 354000000 | BK41: 185000000 | BL41: 187000000 | BM41: 248000000 | BN41: 357000000 | BO41: 214000000 | BP41: 73000000 | BQ41: 198000000 | BR41: 83000000
A42: Central Europe and the Baltics | B42: CEB | C42: Arms imports (SIPRI trend indicator values) | D42: MS.MIL.MPRT.KD | E42: 2091000000 | F42: 1996000000 | G42: 1652000000 | H42: 2179000000 | I42: 3066000000 | J42: 2721000000 | K42: 1773000000 | L42: 1839000000 | M42: 2045000000 | N42: 2373000000 | O42: 2215000000 | P42: 2126000000 | Q42: 2038000000 | R42: 2316000000 | S42: 2589000000 | T42: 2409000000 | U42: 2142000000 | V42: 2257000000 | W42: 3051000000 | X42: 2607000000 | Y42: 2603000000 | Z42: 2405000000 | AA42: 1946000000 | AB42: 1750000000 | AC42: 1961000000 | AD42: 2103000000 | AE42: 2856000000 | AF42: 1776000000 | AG42: 1435000000 | AH42: 1179000000 | AI42: 1595000000 | AJ42: 505000000 | AK42: 440000000 | AL42: 1165000000 | AM42: 226000000 | AN42: 522000000 | AO42: 541000000 | AR42: 360000000 | AS42: 233000000 | AT42: 254000000 | AU42: 369000000 | AV42: 541000000 | AW42: 694000000 | AX42: 1330000000 | AY42: 896000000 | AZ42: 1419000000 | BA42: 1064000000 | BB42: 505000000 | BC42: 453000000 | BD42: 443000000 | BE42: 328000000 | BF42: 287000000 | BG42: 327000000 | BI42: 357000000 | BJ42: 352000000 | BK42: 205000000 | BL42: 354000000 | BM42: 607000000 | BN42: 378000000 | BO42: 868000000 | BP42: 2461000000 | BQ42: 3002000000 | BR42: 4370000000
...

Sheet Exports_Raw
A1: Data Source | B1: World Development Indicators
A3: Last Updated Date | B3: 46303
A5: Country Name | B5: Country Code | C5: Indicator Name | D5: Indicator Code | E5: 1960 | F5: 1961 | G5: 1962 | H5: 1963 | I5: 1964 | J5: 1965 | K5: 1966 | L5: 1967 | M5: 1968 | N5: 1969 | O5: 1970 | P5: 1971 | Q5: 1972 | R5: 1973 | S5: 1974 | T5: 1975 | U5: 1976 | V5: 1977 | W5: 1978 | X5: 1979 | Y5: 1980 | Z5: 1981 | AA5: 1982 | AB5: 1983 | AC5: 1984 | AD5: 1985 | AE5: 1986 | AF5: 1987 | AG5: 1988 | AH5: 1989 | AI5: 1990 | AJ5: 1991 | AK5: 1992 | AL5: 1993 | AM5: 1994 | AN5: 1995 | AO5: 1996 | AP5: 1997 | AQ5: 1998 | AR5: 1999 | AS5: 2000 | AT5: 2001 | AU5: 2002 | AV5: 2003 | AW5: 2004 | AX5: 2005 | AY5: 2006 | AZ5: 2007 | BA5: 2008 | BB5: 2009 | BC5: 2010 | BD5: 2011 | BE5: 2012 | BF5: 2013 | BG5: 2014 | BH5: 2015 | BI5: 2016 | BJ5: 2017 | BK5: 2018 | BL5: 2019 | BM5: 2020 | BN5: 2021 | BO5: 2022 | BP5: 2023 | BQ5: 2024 | BR5: 2025
A6: Aruba | B6: ABW | C6: Arms exports (SIPRI trend indicator values) | D6: MS.MIL.XPRT.KD | AO6: 18000000
A7: Africa Eastern and Southern | B7: AFE | C7: Arms exports (SIPRI trend indicator values) | D7: MS.MIL.XPRT.KD | E7: 27000000 | F7: 33000000 | L7: 9000000 | M7: 9000000 | N7: 13000000 | O7: 2000000 | P7: 7000000 | Q7: 22000000 | R7: 1000000 | S7: 2000000 | T7: 29000000 | U7: 20000000 | Y7: 49000000 | Z7: 62000000 | AA7: 1000000 | AD7: 60000000 | AE7: 29000000 | AF7: 79000000 | AG7: 25000000 | AL7: 56000000 | AU7: 24000000
A8: Afghanistan | B8: AFG | C8: Arms exports (SIPRI trend indicator values) | D8: MS.MIL.XPRT.KD | AK8: 1000000
A9: Africa Western and Central | B9: AFW | C9: Arms exports (SIPRI trend indicator values) | D9: MS.MIL.XPRT.KD | L9: 1000000 | P9: 1000000 | R9: 1000000
A10: Angola | B10: AGO | C10: Arms exports (SIPRI trend indicator values) | D10: MS.MIL.XPRT.KD | X10: 3000000 | Y10: 0 | AU10: 2000000
A11: Albania | B11: ALB | C11: Arms exports (SIPRI trend indicator values) | D11: MS.MIL.XPRT.KD | BD11: 1000000
A12: Andorra | B12: AND | C12: Arms exports (SIPRI trend indicator values) | D12: MS.MIL.XPRT.KD
A13: Arab World | B13: ARB | C13: Arms exports (SIPRI trend indicator values) | D13: MS.MIL.XPRT.KD | E13: 3000000 | F13: 0 | G13: 9000000 | H13: 8000000 | I13: 1000000 | K13: 14000000 | L13: 24000000 | M13: 35000000 | N13: 21000000 | O13: 56000000 | Q13: 2000000 | U13: 4000000 | X13: 454000000 | Z13: 216000000 | AC13: 69000000 | BP13: 183000000
A14: United Arab Emirates | B14: ARE | C14: Arms exports (SIPRI trend indicator values) | D14: MS.MIL.XPRT.KD | S14: 8000000 | AB14: 14000000 | AE14: 22000000 | AF14: 2000000 | AI14: 2000000 | AN14: 28000000 | AO14: 6000000 | AP14: 37000000 | AW14: 3000000 | AX14: 15000000 | AY14: 17000000 | AZ14: 3000000 | BB14: 34000000 | BC14: 39000000 | BD14: 3000000 | BE14: 75000000 | BF14: 115000000 | BG14: 100000000 | BH14: 143000000 | BI14: 111000000 | BJ14: 106000000 | BK14: 120000000 | BL14: 131000000 | BM14: 209000000 | BN14: 57000000 | BO14: 17000000 | BP14: 64000000 | BQ14: 119000000 | BR14: 33000000
A15: Argentina | B15: ARG | C15: Arms exports (SIPRI trend indicator values) | D15: MS.MIL.XPRT.KD | G15: 6000000 | I15: 4000000 | L15: 0 | M15: 8000000 | O15: 0 | Q15: 11000000 | U15: 1000000 | X15: 8000000 | Y15: 1000000 | Z15: 31000000 | AA15: 7000000 | AB15: 5000000 | AF15: 4000000 | AG15: 0 | AI15: 6000000 | AJ15: 0 | AL15: 13000000 | AM15: 5000000 | AN15: 5000000 | AS15: 2000000 | AU15: 2000000 | AY15: 2000000 | BD15: 1000000
A16: Armenia | B16: ARM | C16: Arms exports (SIPRI trend indicator values) | D16: MS.MIL.XPRT.KD | AY16: 4000000
A17: American Samoa | B17: ASM | C17: Arms exports (SIPRI trend indicator values) | D17: MS.MIL.XPRT.KD
A18: Antigua and Barbuda | B18: ATG | C18: Arms exports (SIPRI trend indicator values) | D18: MS.MIL.XPRT.KD
A19: Australia | B19: AUS | C19: Arms exports (SIPRI trend indicator values) | D19: MS.MIL.XPRT.KD | F19: 2000000 | G19: 4000000 | N19: 26000000 | O19: 17000000 | P19: 36000000 | Q19: 6000000 | R19: 72000000 | S19: 92000000 | T19: 131000000 | U19: 113000000 | V19: 62000000 | W19: 21000000 | X19: 22000000 | Y19: 15000000 | Z19: 17000000 | AA19: 26000000 | AB19: 31000000 | AC19: 62000000 | AD19: 10000000 | AE19: 57000000 | AF19: 89000000 | AG19: 12000000 | AH19: 18000000 | AI19: 156000000 | AJ19: 84000000 | AL19: 30000000 | AM19: 24000000 | AN19: 36000000 | AO19: 10000000 | AP19: 14000000 | AQ19: 4000000 | AT19: 43000000 | AU19: 47000000 | AV19: 44000000 | AW19: 2000000 | AX19: 49000000 | AY19: 26000000 | AZ19: 53000000 | BA19: 57000000 | BB19: 86000000 | BC19: 137000000 | BD19: 143000000 | BE19: 45000000 | BF19: 54000000 | BG19: 94000000 | BH19: 79000000 | BI19: 136000000 | BJ19: 101000000 | BK19: 39000000 | BL19: 129000000 | BM19: 406000000 | BN19: 175000000 | BO19: 19000000 | BP19: 81000000 | BQ19: 73000000 | BR19: 108000000
A20: Austria | B20: AUT | C20: Arms exports (SIPRI trend indicator values) | D20: MS.MIL.XPRT.KD | L20: 1000000 | W20: 37000000 | X20: 126000000 | Y20: 54000000 | Z20: 70000000 | AA20: 61000000 | AB20: 58000000 | AC20: 60000000 | AD20: 248000000 | AE20: 40000000 | AF20: 30000000 | AG20: 12000000 | AH20: 12000000 | AI20: 30000000 | AJ20: 20000000 | AK20: 20000000 | AL20: 10000000 | AM20: 17000000 | AO20: 18000000 | AP20: 3000000 | AQ20: 29000000 | AR20: 23000000 | AS20: 23000000 | AT20: 17000000 | AU20: 83000000 | AV20: 2000000 | AW20: 3000000 | AX20: 3000000 | AY20: 62000000 | AZ20: 67000000 | BA20: 14000000 | BB20: 50000000 | BC20: 75000000 | BD20: 62000000 | BE20: 31000000 | BF20: 29000000 | BG20: 16000000 | BH20: 10000000 | BI20: 17000000 | BJ20: 22000000 | BK20: 8000000 | BL20: 3000000 | BM20: 10000000 | BN20: 3000000 | BO20: 3000000 | BP20: 4000000 | BQ20: 23000000 | BR20: 1000000
A21: Azerbaijan | B21: AZE | C21: Arms exports (SIPRI trend indicator values) | D21: MS.MIL.XPRT.KD | BP21: 2000000
A22: Burundi | B22: BDI | C22: Arms exports (SIPRI trend indicator values) | D22: MS.MIL.XPRT.KD
A23: Belgium | B23: BEL | C23: Arms exports (SIPRI trend indicator values) | D23: MS.MIL.XPRT.KD | E23: 3000000 | F23: 0 | G23: 2000000 | H23: 0 | I23: 0 | K23: 12000000 | N23: 5000000 | P23: 0 | X23: 3000000 | Z23: 19000000 | AA23: 41000000 | AB23: 89000000 | AC23: 115000000 | AD23: 4000000 | AE23: 19000000 | AG23: 18000000 | AH23: 36000000 | AI23: 1000000 | AJ23: 1000000 | AM23: 39000000 | AN23: 161000000 | AO23: 61000000 | AP23: 93000000 | AQ23: 46000000 | AR23: 62000000 | AS23: 46000000 | AT23: 37000000 | AU23: 32000000 | AV23: 15000000 | AW23: 47000000 | AX23: 160000000 | AY23: 59000000 | AZ23: 32000000 | BA23: 223000000 | BB23: 242000000 | BC23: 11000000 | BD23: 110000000 | BE23: 21000000 | BF23: 54000000 | BG23: 10000000 | BH23: 12000000 | BI23: 7000000 | BJ23: 17000000 | BK23: 21000000 | BL23: 50000000 | BM23: 19000000 | BN23: 99000000 | BO23: 129000000 | BP23: 41000000 | BQ23: 69000000 | BR23: 86000000
A24: Benin | B24: BEN | C24: Arms exports (SIPRI trend indicator values) | D24: MS.MIL.XPRT.KD
A25: Burkina Faso | B25: BFA | C25: Arms exports (SIPRI trend indicator values) | D25: MS.MIL.XPRT.KD
A26: Bangladesh | B26: BGD | C26: Arms exports (SIPRI trend indicator values) | D26: MS.MIL.XPRT.KD | AC26: 2000000
A27: Bulgaria | B27: BGR | C27: Arms exports (SIPRI trend indicator values) | D27: MS.MIL.XPRT.KD | AB27: 4000000 | AE27: 8000000 | AH27: 8000000 | AI27: 8000000 | AJ27: 44000000 | AK27: 60000000 | AL27: 28000000 | AM27: 56000000 | AN27: 1000000 | AO27: 21000000 | AP27: 8000000 | AQ27: 41000000 | AR27: 172000000 | AS27: 6000000 | AT27: 10000000 | AU27: 37000000 | AV27: 45000000 | AW27: 20000000 | AX27: 87000000 | AY27: 5000000 | AZ27: 9000000 | BA27: 4000000 | BB27: 16000000 | BC27: 4000000 | BD27: 2000000 | BE27: 22000000 | BF27: 23000000 | BG27: 23000000 | BH27: 81000000 | BI27: 83000000 | BJ27: 33000000 | BK27: 14000000 | BL27: 11000000 | BM27: 3000000 | BN27: 7000000 | BO27: 34000000 | BP27: 19000000 | BQ27: 33000000
A28: Bahrain | B28: BHR | C28: Arms exports (SIPRI trend indicator values) | D28: MS.MIL.XPRT.KD | AT28: 2000000
A29: Bahamas, The | B29: BHS | C29: Arms exports (SIPRI trend indicator values) | D29: MS.MIL.XPRT.KD | BH29: 0
A30: Bosnia and Herzegovina | B30: BIH | C30: Arms exports (SIPRI trend indicator values) | D30: MS.MIL.XPRT.KD | AU30: 9000000 | BC30: 0 | BD30: 14000000 | BF30: 3000000 | BO30: 2000000 | BP30: 7000000
A31: Belarus | B31: BLR | C31: Arms exports (SIPRI trend indicator values) | D31: MS.MIL.XPRT.KD | AL31: 8000000 | AN31: 7000000 | AO31: 129000000 | AP31: 402000000 | AQ31: 63000000 | AR31: 454000000 | AS31: 293000000 | AT31: 49000000 | AU31: 64000000 | AV31: 58000000 | AW31: 19000000 | AX31: 53000000 | AY31: 43000000 | AZ31: 5000000 | BA31: 224000000 | BB31: 41000000 | BC31: 161000000 | BD31: 98000000 | BE31: 97000000 | BF31: 269000000 | BG31: 101000000 | BH31: 142000000 | BI31: 152000000 | BJ31: 52000000 | BK31: 86000000 | BL31: 84000000 | BM31: 59000000 | BN31: 111000000 | BO31: 58000000 | BP31: 45000000 | BQ31: 65000000 | BR31: 1000000
A32: Belize | B32: BLZ | C32: Arms exports (SIPRI trend indicator values) | D32: MS.MIL.XPRT.KD
A33: Bermuda | B33: BMU | C33: Arms exports (SIPRI trend indicator values) | D33: MS.MIL.XPRT.KD
A34: Bolivia | B34: BOL | C34: Arms exports (SIPRI trend indicator values) | D34: MS.MIL.XPRT.KD
A35: Brazil | B35: BRA | C35: Arms exports (SIPRI trend indicator values) | D35: MS.MIL.XPRT.KD | E35: 2000000 | F35: 12000000 | N35: 18000000 | P35: 0 | S35: 12000000 | T35: 69000000 | U35: 76000000 | V35: 156000000 | W35: 204000000 | X35: 80000000 | Y35: 160000000 | Z35: 71000000 | AA35: 128000000 | AB35: 204000000 | AC35: 280000000 | AD35: 209000000 | AE35: 140000000 | AF35: 216000000 | AG35: 208000000 | AH35: 53000000 | AI35: 108000000 | AJ35: 129000000 | AK35: 99000000 | AL35: 40000000 | AM35: 54000000 | AN35: 38000000 | AO35: 27000000 | AP35: 27000000 | AQ35: 18000000 | AU35: 21000000 | AW35: 46000000 | AX35: 1000000 | AY35: 44000000 | AZ35: 54000000 | BA35: 93000000 | BB35: 44000000 | BC35: 147000000 | BD35: 32000000 | BE35: 33000000 | BF35: 31000000 | BG35: 31000000 | BH35: 53000000 | BI35: 134000000 | BJ35: 36000000 | BK35: 102000000 | BL35: 21000000 | BM35: 164000000 | BN35: 86000000 | BO35: 10000000 | BP35: 54000000 | BQ35: 112000000 | BR35: 153000000
A36: Barbados | B36: BRB | C36: Arms exports (SIPRI trend indicator values) | D36: MS.MIL.XPRT.KD
A37: Brunei Darussalam | B37: BRN | C37: Arms exports (SIPRI trend indicator values) | D37: MS.MIL.XPRT.KD | BD37: 24000000 | BI37: 12000000
A38: Bhutan | B38: BTN | C38: Arms exports (SIPRI trend indicator values) | D38: MS.MIL.XPRT.KD
A39: Botswana | B39: BWA | C39: Arms exports (SIPRI trend indicator values) | D39: MS.MIL.XPRT.KD
A40: Central African Republic | B40: CAF | C40: Arms exports (SIPRI trend indicator values) | D40: MS.MIL.XPRT.KD
A41: Canada | B41: CAN | C41: Arms exports (SIPRI trend indicator values) | D41: MS.MIL.XPRT.KD | E41: 66000000 | F41: 300000000 | G41: 188000000 | H41: 245000000 | I41: 273000000 | J41: 121000000 | K41: 112000000 | L41: 73000000 | M41: 198000000 | N41: 183000000 | O41: 198000000 | P41: 290000000 | Q41: 323000000 | R41: 118000000 | S41: 90000000 | T41: 59000000 | U41: 259000000 | V41: 138000000 | W41: 177000000 | X41: 163000000 | Y41: 116000000 | Z41: 105000000 | AA41: 237000000 | AB41: 97000000 | AC41: 77000000 | AD41: 83000000 | AE41: 240000000 | AF41: 250000000 | AG41: 124000000 | AH41: 33000000 | AI41: 79000000 | AJ41: 93000000 | AK41: 147000000 | AL41: 152000000 | AM41: 165000000 | AN41: 248000000 | AO41: 168000000 | AP41: 97000000 | AQ41: 39000000 | AR41: 80000000 | AS41: 69000000 | AT41: 124000000 | AU41: 177000000 | AV41: 302000000 | AW41: 289000000 | AX41: 234000000 | AY41: 254000000 | AZ41: 334000000 | BA41: 252000000 | BB41: 198000000 | BC41: 196000000 | BD41: 277000000 | BE41: 258000000 | BF41: 170000000 | BG41: 189000000 | BH41: 298000000 | BI41: 96000000 | BJ41: 63000000 | BK41: 108000000 | BL41: 223000000 | BM41: 123000000 | BN41: 144000000 | BO41: 147000000 | BP41: 276000000 | BQ41: 237000000 | BR41: 312000000
A42: Central Europe and the Baltics | B42: CEB | C42: Arms exports (SIPRI trend indicator values) | D42: MS.MIL.XPRT.KD | E42: 0 | G42: 7000000 | H42: 111000000 | I42: 237000000 | J42: 234000000 | K42: 337000000 | L42: 327000000 | M42: 325000000 | N42: 351000000 | O42: 268000000 | P42: 284000000 | Q42: 294000000 | R42: 212000000 | S42: 258000000 | V42: 404000000 | W42: 368000000 | X42: 291000000 | Y42: 284000000 | Z42: 431000000 | AA42: 325000000 | AB42: 244000000 | AE42: 302000000 | AH42: 53000000 | AI42: 127000000 | AJ42: 112000000 | AM42: 586000000 | AN42: 443000000 | AO42: 276000000 | AP42: 150000000 | AS42: 186000000 | AU42: 223000000 | AX42: 262000000 | AY42: 342000000 | AZ42: 269000000 | BF42: 469000000 | BO42: 1067000000 | BP42: 932000000 | BQ42: 562000000 | BR42: 338000000
...

Sheet Imports_Clean
A1: Country Name | B1: Country Code | C1: Year | D1: Imports_TIV
A2: Africa Eastern and Southern | B2: AFE | C2: 2000 | D2: 522000000
A3: Africa Eastern and Southern | B3: AFE | C3: 2001 | D3: 403000000
A4: Africa Eastern and Southern | B4: AFE | C4: 2005 | D4: 598000000
A5: Africa Eastern and Southern | B5: AFE | C5: 2006 | D5: 1035000000
A6: Africa Eastern and Southern | B6: AFE | C6: 2007 | D6: 1081000000
A7: Africa Eastern and Southern | B7: AFE | C7: 2008 | D7: 768000000
A8: Africa Eastern and Southern | B8: AFE | C8: 2009 | D8: 420000000
A9: Africa Eastern and Southern | B9: AFE | C9: 2011 | D9: 1131000000
A10: Africa Eastern and Southern | B10: AFE | C10: 2012 | D10: 988000000
A11: Africa Eastern and Southern | B11: AFE | C11: 2013 | D11: 563000000
A12: Africa Eastern and Southern | B12: AFE | C12: 2014 | D12: 308000000
A13: Africa Eastern and Southern | B13: AFE | C13: 2015 | D13: 330000000
... A3833: Zimbabwe | B3833: ZWE | C3833: 2023 | D3833: 20000000

Sheet Clean_Data
A1: Country_Name | B1: Country_Code | C1: Year | D1: Exports_TIV | E1: Imports_TIV | F1: Region | G1: Income_Group | H1: Net_Trade_TIV | I1: Total_Volume_TIV
A2: Africa Western and Central | B2: AFW | C2: 2024 | D2: 0 | E2: 433000000 | F2: =_xlfn.LET(_xlpm.r, _xlfn.XLOOKUP(Clean_Data[[#This Row],[Country_Code]], Metadata_Country!$A:$A, Metadata_Country!$B:$B, "Unknown"), IF(OR(_xlpm.r=0, _xlpm.r=""), "Regional Aggregate", _xlpm.r)) -> Regional Aggregate | G2: =_xlfn.LET(_xlpm.ig, _xlfn.XLOOKUP(Clean_Data[[#This Row],[Country_Code]], Metadata_Country!$A:$A, Metadata_Country!$C:$C, "Unknown"), IF(OR(_xlpm.ig=0, _xlpm.ig=""), "Regional Aggregate", _xlpm.ig)) -> Regional Aggregate | H2: =Clean_Data[[#This Row],[Exports_TIV]] - Clean_Data[[#This Row],[Imports_TIV]] -> -433000000 | I2: =Clean_Data[[#This Row],[Exports_TIV]] + Clean_Data[[#This Row],[Imports_TIV]] -> 433000000
A3: Albania | B3: ALB | C3: 2024 | D3: 0 | E3: 38000000 | F3: =_xlfn.LET(_xlpm.r, _xlfn.XLOOKUP(Clean_Data[[#This Row],[Country_Code]], Metadata_Country!$A:$A, Metadata_Country!$B:$B, "Unknown"), IF(OR(_xlpm.r=0, _xlpm.r=""), "Regional Aggregate", _xlpm.r)) -> Europe & Central Asia | G3: =_xlfn.LET(_xlpm.ig, _xlfn.XLOOKUP(Clean_Data[[#This Row],[Country_Code]], Metadata_Country!$A:$A, Metadata_Country!$C:$C, "Unknown"), IF(OR(_xlpm.ig=0, _xlpm.ig=""), "Regional Aggregate", _xlpm.ig)) -> Upper middle income | H3: =Clean_Data[[#This Row],[Exports_TIV]] - Clean_Data[[#This Row],[Imports_TIV]] -> -38000000 | I3: =Clean_Data[[#This Row],[Exports_TIV]] + Clean_Data[[#This Row],[Imports_TIV]] -> 38000000
A4: Algeria | B4: DZA | C4: 2024 | D4: 0 | E4: 205000000 | F4: =_xlfn.LET(_xlpm.r, _xlfn.XLOOKUP(Clean_Data[[#This Row],[Country_Code]], Metadata_Country!$A:$A, Metadata_Country!$B:$B, "Unknown"), IF(OR(_xlpm.r=0, _xlpm.r=""), "Regional Aggregate", _xlpm.r)) -> Middle East & North Africa | G4: =_xlfn.LET(_xlpm.ig, _xlfn.XLOOKUP(Clean_Data[[#This Row],[Country_Code]], Metadata_Country!$A:$A, Metadata_Country!$C:$C, "Unknown"), IF(OR(_xlpm.ig=0, _xlpm.ig=""), "Regional Aggregate", _xlpm.ig)) -> Upper middle income | H4: =Clean_Data[[#This Row],[Exports_TIV]] - Clean_Data[[#This Row],[Imports_TIV]] -> -205000000 | I4: =Clean_Data[[#This Row],[Exports_TIV]] + Clean_Data[[#This Row],[Imports_TIV]] -> 205000000
A5: Angola | B5: AGO | C5: 2024 | D5: 0 | E5: 16000000 | F5: =_xlfn.LET(_xlpm.r, _xlfn.XLOOKUP(Clean_Data[[#This Row],[Country_Code]], Metadata_Country!$A:$A, Metadata_Country!$B:$B, "Unknown"), IF(OR(_xlpm.r=0, _xlpm.r=""), "Regional Aggregate", _xlpm.r)) -> Sub-Saharan Africa | G5: =_xlfn.LET(_xlpm.ig, _xlfn.XLOOKUP(Clean_Data[[#This Row],[Country_Code]], Metadata_Country!$A:$A, Metadata_Country!$C:$C, "Unknown"), IF(OR(_xlpm.ig=0, _xlpm.ig=""), "Regional Aggregate", _xlpm.ig)) -> Lower middle income | H5: =Clean_Data[[#This Row],[Exports_TIV]] - Clean_Data[[#This Row],[Imports_TIV]] -> -16000000 | I5: =Clean_Data[[#This Row],[Exports_TIV]] + Clean_Data[[#This Row],[Imports_TIV]] -> 16000000
A6: Arab World | B6: ARB | C6: 2024 | D6: 0 | E6: 5605000000 | F6: =_xlfn.LET(_xlpm.r, _xlfn.XLOOKUP(Clean_Data[[#This Row],[Country_Code]], Metadata_Country!$A:$A, Metadata_Country!$B:$B, "Unknown"), IF(OR(_xlpm.r=0, _xlpm.r=""), "Regional Aggregate", _xlpm.r)) -> Regional Aggregate | G6: =_xlfn.LET(_xlpm.ig, _xlfn.XLOOKUP(Clean_Data[[#This Row],[Country_Code]], Metadata_Country!$A:$A, Metadata_Country!$C:$C, "Unknown"), IF(OR(_xlpm.ig=0, _xlpm.ig=""), "Regional Aggregate", _xlpm.ig)) -> Regional Aggregate | H6: =Clean_Data[[#This Row],[Exports_TIV]] - Clean_Data[[#This Row],[Imports_TIV]] -> -5605000000 | I6: =Clean_Data[[#This Row],[Exports_TIV]] + Clean_Data[[#This Row],[Imports_TIV]] -> 5605000000
A7: Argentina | B7: ARG | C7: 2024 | D7: 0 | E7: 45000000 | F7: =_xlfn.LET(_xlpm.r, _xlfn.XLOOKUP(Clean_Data[[#This Row],[Country_Code]], Metadata_Country!$A:$A, Metadata_Country!$B:$B, "Unknown"), IF(OR(_xlpm.r=0, _xlpm.r=""), "Regional Aggregate", _xlpm.r)) -> Latin America & Caribbean | G7: =_xlfn.LET(_xlpm.ig, _xlfn.XLOOKUP(Clean_Data[[#This Row],[Country_Code]], Metadata_Country!$A:$A, Metadata_Country!$C:$C, "Unknown"), IF(OR(_xlpm.ig=0, _xlpm.ig=""), "Regional Aggregate", _xlpm.ig)) -> Upper middle income | H7: =Clean_Data[[#This Row],[Exports_TIV]] - Clean_Data[[#This Row],[Imports_TIV]] -> -45000000 | I7: =Clean_Data[[#This Row],[Exports_TIV]] + Clean_Data[[#This Row],[Imports_TIV]] -> 45000000
A8: Armenia | B8: ARM | C8: 2024 | D8: 0 | E8: 32000000 | F8: =_xlfn.LET(_xlpm.r, _xlfn.XLOOKUP(Clean_Data[[#This Row],[Country_Code]], Metadata_Country!$A:$A, Metadata_Country!$B:$B, "Unknown"), IF(OR(_xlpm.r=0, _xlpm.r=""), "Regional Aggregate", _xlpm.r)) -> Europe & Central Asia | G8: =_xlfn.LET(_xlpm.ig, _xlfn.XLOOKUP(Clean_Data[[#This Row],[Country_Code]], Metadata_Country!$A:$A, Metadata_Country!$C:$C, "Unknown"), IF(OR(_xlpm.ig=0, _xlpm.ig=""), "Regional Aggregate", _xlpm.ig)) -> Upper middle income | H8: =Clean_Data[[#This Row],[Exports_TIV]] - Clean_Data[[#This Row],[Imports_TIV]] -> -32000000 | I8: =Clean_Data[[#This Row],[Exports_TIV]] + Clean_Data[[#This Row],[Imports_TIV]] -> 32000000
A9: Australia | B9: AUS | C9: 2024 | D9: 73000000 | E9: 1077000000 | F9: =_xlfn.LET(_xlpm.r, _xlfn.XLOOKUP(Clean_Data[[#This Row],[Country_Code]], Metadata_Country!$A:$A, Metadata_Country!$B:$B, "Unknown"), IF(OR(_xlpm.r=0, _xlpm.r=""), "Regional Aggregate", _xlpm.r)) -> East Asia & Pacific | G9: =_xlfn.LET(_xlpm.ig, _xlfn.XLOOKUP(Clean_Data[[#This Row],[Country_Code]], Metadata_Country!$A:$A, Metadata_Country!$C:$C, "Unknown"), IF(OR(_xlpm.ig=0, _xlpm.ig=""), "Regional Aggregate", _xlpm.ig)) -> High income | H9: =Clean_Data[[#This Row],[Exports_TIV]] - Clean_Data[[#This Row],[Imports_TIV]] -> -1004000000 | I9: =Clean_Data[[#This Row],[Exports_TIV]] + Clean_Data[[#This Row],[Imports_TIV]] -> 1150000000
A10: Austria | B10: AUT | C10: 2024 | D10: 23000000 | E10: 13000000 | F10: =_xlfn.LET(_xlpm.r, _xlfn.XLOOKUP(Clean_Data[[#This Row],[Country_Code]], Metadata_Country!$A:$A, Metadata_Country!$B:$B, "Unknown"), IF(OR(_xlpm.r=0, _xlpm.r=""), "Regional Aggregate", _xlpm.r)) -> Europe & Central Asia | G10: =_xlfn.LET(_xlpm.ig, _xlfn.XLOOKUP(Clean_Data[[#This Row],[Country_Code]], Metadata_Country!$A:$A, Metadata_Country!$C:$C, "Unknown"), IF(OR(_xlpm.ig=0, _xlpm.ig=""), "Regional Aggregate", _xlpm.ig)) -> High income | H10: =Clean_Data[[#This Row],[Exports_TIV]] - Clean_Data[[#This Row],[Imports_TIV]] -> 10000000 | I10: =Clean_Data[[#This Row],[Exports_TIV]] + Clean_Data[[#This Row],[Imports_TIV]] -> 36000000
A11: Azerbaijan | B11: AZE | C11: 2024 | D11: 0 | E11: 75000000 | F11: =_xlfn.LET(_xlpm.r, _xlfn.XLOOKUP(Clean_Data[[#This Row],[Country_Code]], Metadata_Country!$A:$A, Metadata_Country!$B:$B, "Unknown"), IF(OR(_xlpm.r=0, _xlpm.r=""), "Regional Aggregate", _xlpm.r)) -> Europe & Central Asia | G11: =_xlfn.LET(_xlpm.ig, _xlfn.XLOOKUP(Clean_Data[[#This Row],[Country_Code]], Metadata_Country!$A:$A, Metadata_Country!$C:$C, "Unknown"), IF(OR(_xlpm.ig=0, _xlpm.ig=""), "Regional Aggregate", _xlpm.ig)) -> Upper middle income | H11: =Clean_Data[[#This Row],[Exports_TIV]] - Clean_Data[[#This Row],[Imports_TIV]] -> -75000000 | I11: =Clean_Data[[#This Row],[Exports_TIV]] + Clean_Data[[#This Row],[Imports_TIV]] -> 75000000
A12: Bahrain | B12: BHR | C12: 2024 | D12: 0 | E12: 850000000 | F12: =_xlfn.LET(_xlpm.r, _xlfn.XLOOKUP(Clean_Data[[#This Row],[Country_Code]], Metadata_Country!$A:$A, Metadata_Country!$B:$B, "Unknown"), IF(OR(_xlpm.r=0, _xlpm.r=""), "Regional Aggregate", _xlpm.r)) -> Middle East & North Africa | G12: =_xlfn.LET(_xlpm.ig, _xlfn.XLOOKUP(Clean_Data[[#This Row],[Country_Code]], Metadata_Country!$A:$A, Metadata_Country!$C:$C, "Unknown"), IF(OR(_xlpm.ig=0, _xlpm.ig=""), "Regional Aggregate", _xlpm.ig)) -> High income | H12: =Clean_Data[[#This Row],[Exports_TIV]] - Clean_Data[[#This Row],[Imports_TIV]] -> -850000000 | I12: =Clean_Data[[#This Row],[Exports_TIV]] + Clean_Data[[#This Row],[Imports_TIV]] -> 850000000
A13: Bangladesh | B13: BGD | C13: 2024 | D13: 0 | E13: 70000000 | F13: =_xlfn.LET(_xlpm.r, _xlfn.XLOOKUP(Clean_Data[[#This Row],[Country_Code]], Metadata_Country!$A:$A, Metadata_Country!$B:$B, "Unknown"), IF(OR(_xlpm.r=0, _xlpm.r=""), "Regional Aggregate", _xlpm.r)) -> South Asia | G13: =_xlfn.LET(_xlpm.ig, _xlfn.XLOOKUP(Clean_Data[[#This Row],[Country_Code]], Metadata_Country!$A:$A, Metadata_Country!$C:$C, "Unknown"), IF(OR(_xlpm.ig=0, _xlpm.ig=""), "Regional Aggregate", _xlpm.ig)) -> Lower middle income | H13: =Clean_Data[[#This Row],[Exports_TIV]] - Clean_Data[[#This Row],[Imports_TIV]] -> -70000000 | I13: =Clean_Data[[#This Row],[Exports_TIV]] + Clean_Data[[#This Row],[Imports_TIV]] -> 70000000
... A3986: Zimbabwe | B3986: ZWE | C3986: 2000 | D3986: 0 | E3986: 8000000 | F3986: =_xlfn.LET(_xlpm.r, _xlfn.XLOOKUP(Clean_Data[[#This Row],[Country_Code]], Metadata_Country!$A:$A, Metadata_Country!$B:$B, "Unknown"), IF(OR(_xlpm.r=0, _xlpm.r=""), "Regional Aggregate", _xlpm.r)) -> Sub-Saharan Africa | G3986: =_xlfn.LET(_xlpm.ig, _xlfn.XLOOKUP(Clean_Data[[#This Row],[Country_Code]], Metadata_Country!$A:$A, Metadata_Country!$C:$C, "Unknown"), IF(OR(_xlpm.ig=0, _xlpm.ig=""), "Regional Aggregate", _xlpm.ig)) -> Lower middle income | H3986: =Clean_Data[[#This Row],[Exports_TIV]] - Clean_Data[[#This Row],[Imports_TIV]] -> -8000000 | I3986: =Clean_Data[[#This Row],[Exports_TIV]] + Clean_Data[[#This Row],[Imports_TIV]] -> 8000000

Sheet Analysis
B2: Global Arms Transfers & Defense Alignment (2000–2024)
B3: Source: World Bank WDI / SIPRI TIV Database | Master Dataset Analysis
B5: METRIC | C5: VALUE (TIV) | E5: Rank | F5: Exporter Country | G5: ISO-3 | H5: Cumulative Exports (TIV) | I5: Global Share (%) | K5: Rank | L5: Importer Country | M5: ISO-3 | N5: Cumulative Imports (TIV) | O5: Global Share (%)
B6: Total Global Trade Volume (National) | C6: =SUMIFS(Clean_Data[Total_Volume_TIV], Clean_Data[Region], "<>Regional Aggregate") -> 1282812000000 | E6: {=_xlfn.SEQUENCE(10)} -> 1 | F6: {=_xlfn.LET( _xlpm.countries, _xlfn.UNIQUE(_xlfn._xlws.FILTER(Clean_Data[Country_Name], Clean_Data[Region]<>"Regional Aggregate")), _xlpm.exports, _xlfn.MAP(_xlpm.countries, _xlfn.LAMBDA(_xlpm.c, SUMIFS(Clean_Data[Exports_TIV], Clean_Data[Country_Name], _xlpm.c))), _xlpm.codes, _xlfn.MAP(_xlpm.countries, _xlfn.LAMBDA(_xlpm.c, _xlfn.XLOOKUP(_xlpm.c, Clean_Data[Country_Name], Clean_Data[Country_Code]))), _xlpm.table, _xlfn.HSTACK(_xlpm.countries, _xlpm.codes, _xlpm.exports), _xlfn.TAKE(_xlfn._xlws.SORT(_xlpm.table, 3, -1), 10) )} -> United States | G6: USA | H6: 222364000000 | I6: {=INDEX(_xlfn.ANCHORARRAY(F6), , 3) / $C$7} -> 0.34403884 | K6: {=_xlfn.SEQUENCE(10)} -> 1 | L6: {=_xlfn.LET( _xlpm.countries, _xlfn.UNIQUE(_xlfn._xlws.FILTER(Clean_Data[Country_Name], Clean_Data[Region]<>"Regional Aggregate")), _xlpm.imports, _xlfn.MAP(_xlpm.countries, _xlfn.LAMBDA(_xlpm.c, SUMIFS(Clean_Data[Imports_TIV], Clean_Data[Country_Name], _xlpm.c))), _xlpm.codes, _xlfn.MAP(_xlpm.countries, _xlfn.LAMBDA(_xlpm.c, _xlfn.XLOOKUP(_xlpm.c, Clean_Data[Country_Name], Clean_Data[Country_Code]))), _xlpm.table, _xlfn.HSTACK(_xlpm.countries, _xlpm.codes, _xlpm.imports), _xlfn.TAKE(_xlfn._xlws.SORT(_xlpm.table, 3, -1), 10) )} -> India | M6: IND | N6: 62908000000 | O6: {=INDEX(_xlfn.ANCHORARRAY(L6), , 3) / $C$8} -> 0.098837666
B7: Total Global Exports (National) | C7: =SUMIFS(Clean_Data[Exports_TIV], Clean_Data[Region], "<>Regional Aggregate") -> 646334000000 | E7: 2 | F7: Russian Federation | G7: RUS | H7: 134441000000 | I7: 0.20800546 | K7: 2 | L7: China | M7: CHN | N7: 40927000000 | O7: 0.064302301
B8: Total Global Imports (National) | C8: =SUMIFS(Clean_Data[Imports_TIV], Clean_Data[Region], "<>Regional Aggregate") -> 636478000000 | E8: 3 | F8: France | G8: FRA | H8: 50421000000 | I8: 0.07801075 | K8: 3 | L8: Saudi Arabia | M8: SAU | N8: 37196000000 | O8: 0.058440355
B9: Net Arms Exporter Surplus / Deficit | C9: =C7 - C8 -> 9856000000 | E9: 4 | F9: Germany | G9: DEU | H9: 41813000000 | I9: 0.064692558 | K9: 4 | L9: Korea, Rep. | M9: KOR | N9: 24721000000 | O9: 0.038840306
B10: Distinct Sovereign Entities Tracked | C10: {=COUNTA(_xlfn.UNIQUE(_xlfn._xlws.FILTER(Clean_Data[Country_Code], Clean_Data[Region]<>"Regional Aggregate")))} -> 181 | E10: 5 | F10: China | G10: CHN | H10: 30914000000 | I10: 0.04782976 | K10: 5 | L10: United Arab Emirates | M10: ARE | N10: 24693000000 | O10: 0.038796313
B11: Timeline Period | C11: =MIN(Clean_Data[Year]) & " – " & MAX(Clean_Data[Year]) -> 2000 – 2024 | E11: 6 | F11: United Kingdom | G11: GBR | H11: 27483000000 | I11: 0.042521359 | K11: 6 | L11: Australia | M11: AUS | N11: 23363000000 | O11: 0.036706689
E12: 7 | F12: Italy | G12: ITA | H12: 18116000000 | I12: 0.028028852 | K12: 7 | L12: Pakistan | M12: PAK | N12: 22867000000 | O12: 0.0359274
E13: 8 | F13: Israel | G13: ISR | H13: 16890000000 | I13: 0.026132 | K13: 8 | L13: Egypt, Arab Rep. | M13: EGY | N13: 22095000000 | O13: 0.034714476
E14: 9 | F14: Spain | G14: ESP | H14: 13942000000 | I14: 0.021570891 | K14: 9 | L14: United States | M14: USA | N14: 18178000000 | O14: 0.028560296
E15: 10 | F15: Netherlands | G15: NLD | H15: 12579000000 | I15: 0.019462074 | K15: 10 | L15: Algeria | M15: DZA | N15: 17187000000 | O15: 0.02700329
B20: Region | C20: Exports (TIV) | D20: Imports (TIV) | E20: Net Trade (TIV) | F20: Trade Orientation
B21: {=_xlfn.LET( _xlpm.regs, _xlfn._xlws.SORT(_xlfn.UNIQUE(_xlfn._xlws.FILTER(Clean_Data[Region], (Clean_Data[Region]<>"Regional Aggregate")*(Clean_Data[Region]<>"Unknown")*(Clean_Data[Region]<>"")))), _xlpm.regs )} -> East Asia & Pacific | C21: {=_xlfn.MAP(_xlfn.ANCHORARRAY(B21), _xlfn.LAMBDA(_xlpm.r, SUMIFS(Clean_Data[Exports_TIV], Clean_Data[Region], _xlpm.r)))} -> 44039000000 | D21: {=_xlfn.MAP(_xlfn.ANCHORARRAY(B21), _xlfn.LAMBDA(_xlpm.r, SUMIFS(Clean_Data[Imports_TIV], Clean_Data[Region], _xlpm.r)))} -> 154429000000 | E21: {=_xlfn.ANCHORARRAY(C21) -_xlfn.ANCHORARRAY( D21)} -> -110390000000 | F21: {=_xlfn.MAP(_xlfn.ANCHORARRAY(E21), _xlfn.LAMBDA(_xlpm.val, IF(_xlpm.val > 0, "Net Exporter (Supplier)", "Net Importer (Dependent)")))} -> Net Importer (Dependent)
B22: Europe & Central Asia | C22: 348368000000 | D22: 140914000000 | E22: 207454000000 | F22: Net Exporter (Supplier)
B23: Latin America & Caribbean | C23: 1604000000 | D23: 27613000000 | E23: -26009000000 | F23: Net Importer (Dependent)
B24: Middle East & North Africa | C24: 21385000000 | D24: 199652000000 | E24: -178267000000 | F24: Net Importer (Dependent)
B25: North America | C25: 227402000000 | D25: 25127000000 | E25: 202275000000 | F25: Net Exporter (Supplier)
B26: South Asia | C26: 804000000 | D26: 69341000000 | E26: -68537000000 | F26: Net Importer (Dependent)
B27: Sub-Saharan Africa | C27: 2732000000 | D27: 19402000000 | E27: -16670000000 | F27: Net Importer (Dependent)
B32: ANNUAL EXPORT TRENDS: TOP 5 GLOBAL SUPPLIERS (2000–2024)
B34: Year | C34: United States | D34: Russian Federation | E34: France | F34: Germany | G34: China | H34: Top 5 Combined (TIV)
B35: {=_xlfn.SEQUENCE(25, 1, 2000, 1)} -> 2000 | C35: {=_xlfn.MAP(_xlfn.ANCHORARRAY(B35), _xlfn.LAMBDA(_xlpm.y, SUMIFS(Clean_Data[Exports_TIV], Clean_Data[Country_Code], "USA", Clean_Data[Year], _xlpm.y)))} -> 7678000000 | D35: {=_xlfn.MAP(_xlfn.ANCHORARRAY(B35), _xlfn.LAMBDA(_xlpm.y, SUMIFS(Clean_Data[Exports_TIV], Clean_Data[Country_Code], "RUS", Clean_Data[Year], _xlpm.y)))} -> 4496000000 | E35: {=_xlfn.MAP(_xlfn.ANCHORARRAY(B35), _xlfn.LAMBDA(_xlpm.y, SUMIFS(Clean_Data[Exports_TIV], Clean_Data[Country_Code], "FRA", Clean_Data[Year], _xlpm.y)))} -> 966000000 | F35: {=_xlfn.MAP(_xlfn.ANCHORARRAY(B35), _xlfn.LAMBDA(_xlpm.y, SUMIFS(Clean_Data[Exports_TIV], Clean_Data[Country_Code], "DEU", Clean_Data[Year], _xlpm.y)))} -> 1672000000 | G35: {=_xlfn.MAP(_xlfn.ANCHORARRAY(B35), _xlfn.LAMBDA(_xlpm.y, SUMIFS(Clean_Data[Exports_TIV], Clean_Data[Country_Code], "CHN", Clean_Data[Year], _xlpm.y)))} -> 309000000 | H35: {=_xlfn.BYROW(_xlfn.HSTACK(_xlfn.ANCHORARRAY(C35),_xlfn.ANCHORARRAY( D35),_xlfn.ANCHORARRAY( E35),_xlfn.ANCHORARRAY( F35),_xlfn.ANCHORARRAY( G35)), _xlfn.LAMBDA(_xlpm.r, SUM(_xlpm.r)))} -> 15121000000
B36: 2001 | C36: 5591000000 | D36: 5250000000 | E36: 1311000000 | F36: 851000000 | G36: 510000000 | H36: 13513000000
B37: 2002 | C37: 4872000000 | D37: 5735000000 | E37: 1375000000 | F37: 889000000 | G37: 524000000 | H37: 13395000000
B38: 2003 | C38: 5684000000 | D38: 5266000000 | E38: 1348000000 | F38: 1632000000 | G38: 701000000 | H38: 14631000000
B39: 2004 | C39: 6869000000 | D39: 6353000000 | E39: 2117000000 | F39: 1090000000 | G39: 408000000 | H39: 16837000000
B40: 2005 | C40: 6724000000 | D40: 5199000000 | E40: 1645000000 | F40: 2083000000 | G40: 341000000 | H40: 15992000000
B41: 2006 | C41: 7497000000 | D41: 5182000000 | E41: 1484000000 | F41: 2482000000 | G41: 769000000 | H41: 17414000000
B42: 2007 | C42: 7870000000 | D42: 5596000000 | E42: 2145000000 | F42: 3291000000 | G42: 520000000 | H42: 19422000000
B43: 2008 | C43: 7089000000 | D43: 5998000000 | E43: 1872000000 | F43: 2378000000 | G43: 598000000 | H43: 17935000000
B44: 2009 | C44: 7151000000 | D44: 5126000000 | E44: 1845000000 | F44: 2207000000 | G44: 1138000000 | H44: 17467000000
B45: 2010 | C45: 8354000000 | D45: 6227000000 | E45: 888000000 | F45: 2364000000 | G45: 1531000000 | H45: 19364000000
B46: 2011 | C46: 9041000000 | D46: 8793000000 | E46: 2079000000 | F46: 1203000000 | G46: 1308000000 | H46: 22424000000
B47: 2012 | C47: 8965000000 | D47: 8335000000 | E47: 1338000000 | F47: 715000000 | G47: 1499000000 | H47: 20852000000
... B59: 2024 | C59: 13651000000 | D59: 1994000000 | E59: 2472000000 | F59: 2108000000 | G59: 1294000000 | H59: 21519000000

Sheet Dashboard
B2: Global Defense Trade: Trajectories & Strategic Alignment (2000–2024)
B3: World Bank / SIPRI TIV Trend Visualizations

Sheet Pivot_Table
A1: Region | B1: (Multiple Items)
B3: Column Labels
B4: 2000 | D4: 2001 | F4: 2002 | H4: 2003 | J4: 2004 | L4: 2005 | N4: 2006 | P4: 2007 | R4: 2008 | T4: 2009 | V4: 2010 | X4: 2011 | Z4: 2012 | AB4: 2013 | AD4: 2014 | AF4: 2015 | AH4: 2016 | AJ4: 2017 | AL4: 2018 | AN4: 2019 | AP4: 2020 | AR4: 2021 | AT4: 2022 | AV4: 2023 | AX4: 2024 | AZ4: Total Net Trade (TIV) | BA4: Total Total Volume (TIV)
